[INFO]2022-07-03 11:27:20,607: #################################################################
[INFO]2022-07-03 11:27:20,608: Perform log
[INFO]2022-07-03 11:27:20,608: #################################################################
[INFO]2022-07-03 11:27:20,610: name:56:Use case writer:zpou
[INFO]2022-07-03 11:27:20,614: Enter function : flow_weather()
[INFO]2022-07-03 11:27:20,615: Input parameter : update_dict, value : value is empty.
[INFO]2022-07-03 11:27:20,616: Enter function : flow_login()
[INFO]2022-07-03 11:27:20,616: Input parameter : update_dict, value : value is empty.
[INFO]2022-07-03 11:27:20,620: apileft:56:interface message: {'url': '/api/mgr/signin', 'type': 'post', 'api_type': 'http', 'location_interface': 'my_api_login', 'request': {'username': 'byhy', 'password': '88888888'}, 'reponses_type': 'json', 'Content-Type': 'data'}
[INFO]2022-07-03 11:27:20,623: apileft:65:requests url: http://127.0.0.1:80/api/mgr/signin
[INFO]2022-07-03 11:27:20,625: apileft:69:request method: post
[INFO]2022-07-03 11:27:20,626: apileft:74:requests parameter: {'username': 'byhy', 'password': '88888888'}
[INFO]2022-07-03 11:27:20,627: apileft:80:headers: {'content-type': 'application/x-www-form-urlencoded; charset=UTF-8', 'x-requested-with': 'XMLHttpRequest', 'sec-ch-ua-platform': 'Windows', 'Sec-Fetch-Site': 'same-origin', 'Sec-Fetch-Mode': 'cors', 'Sec-Fetch-Dest': 'empty', 'Cookie': 'csrftoken = ftE3dWoJqtQx963qTSGEtPPD62a3dntwBQWBacLeot1E1ntBWX7DE75O6EhU53kg'}
[DEBUG]2022-07-03 11:27:20,675: Starting new HTTP connection (1): 127.0.0.1:80
[ERROR]2022-07-03 11:27:22,679: post:61:HTTPConnectionPool(host='127.0.0.1', port=80): Max retries exceeded with url: /api/mgr/signin (Caused by NewConnectionError('<urllib3.connection.HTTPConnection object at 0x00000272703E1870>: Failed to establish a new connection: [WinError 10061] 由于目标计算机积极拒绝，无法连接。'))
[ERROR]2022-07-03 11:27:22,748: post:62:Traceback (most recent call last):
  File "D:\install\python\lib\site-packages\urllib3\connection.py", line 174, in _new_conn
    conn = connection.create_connection(
  File "D:\install\python\lib\site-packages\urllib3\util\connection.py", line 95, in create_connection
    raise err
  File "D:\install\python\lib\site-packages\urllib3\util\connection.py", line 85, in create_connection
    sock.connect(sa)
ConnectionRefusedError: [WinError 10061] 由于目标计算机积极拒绝，无法连接。

During handling of the above exception, another exception occurred:

Traceback (most recent call last):
  File "D:\install\python\lib\site-packages\urllib3\connectionpool.py", line 703, in urlopen
    httplib_response = self._make_request(
  File "D:\install\python\lib\site-packages\urllib3\connectionpool.py", line 398, in _make_request
    conn.request(method, url, **httplib_request_kw)
  File "D:\install\python\lib\site-packages\urllib3\connection.py", line 239, in request
    super(HTTPConnection, self).request(method, url, body=body, headers=headers)
  File "D:\install\python\lib\http\client.py", line 1282, in request
    self._send_request(method, url, body, headers, encode_chunked)
  File "D:\install\python\lib\http\client.py", line 1328, in _send_request
    self.endheaders(body, encode_chunked=encode_chunked)
  File "D:\install\python\lib\http\client.py", line 1277, in endheaders
    self._send_output(message_body, encode_chunked=encode_chunked)
  File "D:\install\python\lib\http\client.py", line 1037, in _send_output
    self.send(msg)
  File "D:\install\python\lib\http\client.py", line 975, in send
    self.connect()
  File "D:\install\python\lib\site-packages\urllib3\connection.py", line 205, in connect
    conn = self._new_conn()
  File "D:\install\python\lib\site-packages\urllib3\connection.py", line 186, in _new_conn
    raise NewConnectionError(
urllib3.exceptions.NewConnectionError: <urllib3.connection.HTTPConnection object at 0x00000272703E1870>: Failed to establish a new connection: [WinError 10061] 由于目标计算机积极拒绝，无法连接。

During handling of the above exception, another exception occurred:

Traceback (most recent call last):
  File "D:\install\python\lib\site-packages\requests\adapters.py", line 440, in send
    resp = conn.urlopen(
  File "D:\install\python\lib\site-packages\urllib3\connectionpool.py", line 785, in urlopen
    retries = retries.increment(
  File "D:\install\python\lib\site-packages\urllib3\util\retry.py", line 592, in increment
    raise MaxRetryError(_pool, url, error or ResponseError(cause))
urllib3.exceptions.MaxRetryError: HTTPConnectionPool(host='127.0.0.1', port=80): Max retries exceeded with url: /api/mgr/signin (Caused by NewConnectionError('<urllib3.connection.HTTPConnection object at 0x00000272703E1870>: Failed to establish a new connection: [WinError 10061] 由于目标计算机积极拒绝，无法连接。'))

During handling of the above exception, another exception occurred:

Traceback (most recent call last):
  File "D:\my_api\Public_variable\apitest.py", line 58, in post
    respones = self.begin.post(url=param[3], data=param[2], json=param[1], headers=param[4])
  File "D:\install\python\lib\site-packages\requests\sessions.py", line 577, in post
    return self.request('POST', url, data=data, json=json, **kwargs)
  File "D:\install\python\lib\site-packages\requests\sessions.py", line 529, in request
    resp = self.send(prep, **send_kwargs)
  File "D:\install\python\lib\site-packages\requests\sessions.py", line 645, in send
    r = adapter.send(request, **kwargs)
  File "D:\install\python\lib\site-packages\requests\adapters.py", line 519, in send
    raise ConnectionError(e, request=request)
requests.exceptions.ConnectionError: HTTPConnectionPool(host='127.0.0.1', port=80): Max retries exceeded with url: /api/mgr/signin (Caused by NewConnectionError('<urllib3.connection.HTTPConnection object at 0x00000272703E1870>: Failed to establish a new connection: [WinError 10061] 由于目标计算机积极拒绝，无法连接。'))

[ERROR]2022-07-03 11:27:22,751: flow_login:29:local variable 'respones_reslut' referenced before assignment
[ERROR]2022-07-03 11:27:22,753: flow_login:30:Traceback (most recent call last):
  File "D:\my_api\confdb\flow\user\user.py", line 26, in flow_login
    login_result = self.api_login_byhy(login_dict)
  File "D:\my_api\confdb\api\user\user.py", line 19, in api_login_byhy
    return self.post(Tim_api_mgr_signin, request_dict)
  File "D:\my_api\Public_variable\apitest.py", line 64, in post
    return respones_reslut
UnboundLocalError: local variable 'respones_reslut' referenced before assignment

[INFO]2022-07-03 11:27:22,755: flow_weather:29:TypeError: update_dict is not dict!
[ERROR]2022-07-03 11:27:22,756: apileft:82:name 'false' is not defined
[ERROR]2022-07-03 11:27:22,757: apileft:83:Traceback (most recent call last):
  File "D:\my_api\tc_play\requetes.py", line 55, in apileft
    contex = eval(context)
  File "<string>", line 16, in <module>
NameError: name 'false' is not defined

[ERROR]2022-07-03 11:27:22,758: post:61:local variable 'parm' referenced before assignment
[ERROR]2022-07-03 11:27:22,760: post:62:Traceback (most recent call last):
  File "D:\my_api\Public_variable\apitest.py", line 50, in post
    param = self.Requests.apileft(api, dict_request)
  File "D:\my_api\tc_play\requetes.py", line 85, in apileft
    return parm[0], parm[1], parm[2], url, headers, request_method
UnboundLocalError: local variable 'parm' referenced before assignment

[ERROR]2022-07-03 11:27:22,761: flow_weather:35:local variable 'respones_reslut' referenced before assignment
[ERROR]2022-07-03 11:27:22,763: flow_weather:36:Traceback (most recent call last):
  File "D:\my_api\confdb\flow\user\client.py", line 30, in flow_weather
    weather_result = self.api_get_apone(weather_dict)
  File "D:\my_api\confdb\api\user\client.py", line 19, in api_get_apone
    return self.post(Tim_api_mgr_customers, request_dict)
  File "D:\my_api\Public_variable\apitest.py", line 64, in post
    return respones_reslut
UnboundLocalError: local variable 'respones_reslut' referenced before assignment

