[INFO]2022-07-03 01:10:34,764: #################################################################
[INFO]2022-07-03 01:10:34,764: Perform log
[INFO]2022-07-03 01:10:34,764: #################################################################
[INFO]2022-07-03 01:10:34,765: name:56:Use case writer:zpou
[ERROR]2022-07-03 01:10:34,785: test_weather:25:Logger._log() got an unexpected keyword argument 'depth'
[ERROR]2022-07-03 01:10:34,786: test_weather:26:Traceback (most recent call last):
  File "D:\my_api\Public_variable\clog.py", line 150, in enter
    ulog.info('Enter function : {func}()'.format(func=sys._getframe(depth).f_code.co_name), depth=3)
  File "D:\install\python\lib\logging\__init__.py", line 1477, in info
    self._log(INFO, msg, args, **kwargs)
TypeError: Logger._log() got an unexpected keyword argument 'depth'

During handling of the above exception, another exception occurred:

Traceback (most recent call last):
  File "D:\my_api\confdb\testcase\user.py", line 22, in test_weather
    b_ret, weather_result = self.flow_weather()
  File "D:\my_api\confdb\flow\user\client.py", line 14, in flow_weather
    self.Clog.enter()
  File "D:\my_api\Public_variable\clog.py", line 163, in enter
    ulog.info(traceback.format_exc(),depth=3)
  File "D:\install\python\lib\logging\__init__.py", line 1477, in info
    self._log(INFO, msg, args, **kwargs)
TypeError: Logger._log() got an unexpected keyword argument 'depth'

